Workbook

Sheet formules
A1: Colonne | B1: formules
A2: Nombre de communes | B2: "=COUNTIFS(T_HDF[Code_EPCI];A3)"
A3: Superficie (km²) | B3: "=SUMIFS(T_HDF[Superficie_km2];T_HDF[Code_EPCI];A3)"
A4: Population 2017 | B4: "=XLOOKUP(T_Analyse[Code_EPCI];T_EPCI[Code_EPCI];T_EPCI[Population_2017])"
A5: Population 2023 | B5: "=XLOOKUP(T_Analyse[Code_EPCI];T_EPCI[Code_EPCI];T_EPCI[Population_2023])"
A6: Niveau de vie médian 2023 | B6: "=XLOOKUP(T_Analyse[Code_EPCI];T_EPCI[Code_EPCI];T_EPCI[Niveau_vie_median_2023])"
A7: Taux de pauvreté 2023
A8: Évolution de la population (%)
A9: Nombre de personnes pauvres
A10: Densité (hab/km²)

Sheet Analyse
A2: Code_EPCI | B2: Nom_EPCI | C2: Nombre de communes | D2: Superficie (km²) | E2: Population 2017 | F2: Population 2023 | G2: Niveau de vie médian 2023 | H2: Taux de pauvreté 2023 | I2: Évolution de la population (%) | J2: Nombre de personnes pauvres | K2: Densité (hab/km²) | L2: Résultat by Xavier | M2: Formule by Xavier
A3: 248000531 | B3: CA Amiens Métropole | C3: =COUNTIFS(T_HDF[Code_EPCI],A3) -> 39 | D3: =SUMIFS(T_HDF[Superficie_km2],T_HDF[Code_EPCI],A3) -> 351.47 | E3: {=_xlfn.XLOOKUP(T_Analyse[Code_EPCI],INSEE_EPCI!$A$2:$A$93,INSEE_EPCI!$C$2:$C$93)} -> 180816 | F3: {=_xlfn.XLOOKUP(T_Analyse[Code_EPCI],INSEE_EPCI!$A$2:$A$93,INSEE_EPCI!$D$2:$D$93)} -> 184392 | G3: {=_xlfn.XLOOKUP(T_Analyse[Code_EPCI],INSEE_EPCI!$A$2:$A$93,INSEE_EPCI!$E$2:$E$93)} -> 23640 | H3: {=_xlfn.XLOOKUP(T_Analyse[Code_EPCI],INSEE_EPCI!$A$2:$A$93,INSEE_EPCI!$F$2:$F$93)} -> 23.5 | I3: =(F3-E3)/E3 -> 0.019777011 | J3: =H3*F3/100 -> 43332.12 | K3: =F3/D3 -> 524.63084 | L3: =sum(T_Analyse[Population 2023]-T_Analyse[Formule by Xavier]) -> 0 | M3: =SUMIFS(T_HDF[Population],T_HDF[Code_EPCI],T_Analyse[Code_EPCI]) -> 184392
A4: 200071785 | B4: CA Chauny Tergnier La Fère | C4: =COUNTIFS(T_HDF[Code_EPCI],A4) -> 48 | D4: =SUMIFS(T_HDF[Superficie_km2],T_HDF[Code_EPCI],A4) -> 385.08 | E4: {=_xlfn.XLOOKUP(T_Analyse[Code_EPCI],INSEE_EPCI!$A$2:$A$93,INSEE_EPCI!$C$2:$C$93)} -> 55470 | F4: {=_xlfn.XLOOKUP(T_Analyse[Code_EPCI],INSEE_EPCI!$A$2:$A$93,INSEE_EPCI!$D$2:$D$93)} -> 54027 | G4: {=_xlfn.XLOOKUP(T_Analyse[Code_EPCI],INSEE_EPCI!$A$2:$A$93,INSEE_EPCI!$E$2:$E$93)} -> 22590 | H4: {=_xlfn.XLOOKUP(T_Analyse[Code_EPCI],INSEE_EPCI!$A$2:$A$93,INSEE_EPCI!$F$2:$F$93)} -> 21.6 | I4: =(F4-E4)/E4 -> -0.026014062 | J4: =H4*F4/100 -> 11669.832 | K4: =F4/D4 -> 140.30072 | L4: =sum(T_Analyse[Population 2023]-T_Analyse[Formule by Xavier]) -> 0 | M4: =SUMIFS(T_HDF[Population],T_HDF[Code_EPCI],T_Analyse[Code_EPCI]) -> 54027
A5: 245901152 | B5: CA Coeur d'Ostrevent | C5: =COUNTIFS(T_HDF[Code_EPCI],A5) -> 20 | D5: =SUMIFS(T_HDF[Superficie_km2],T_HDF[Code_EPCI],A5) -> 138.3 | E5: {=_xlfn.XLOOKUP(T_Analyse[Code_EPCI],INSEE_EPCI!$A$2:$A$93,INSEE_EPCI!$C$2:$C$93)} -> 70957 | F5: {=_xlfn.XLOOKUP(T_Analyse[Code_EPCI],INSEE_EPCI!$A$2:$A$93,INSEE_EPCI!$D$2:$D$93)} -> 69764 | G5: {=_xlfn.XLOOKUP(T_Analyse[Code_EPCI],INSEE_EPCI!$A$2:$A$93,INSEE_EPCI!$E$2:$E$93)} -> 22340 | H5: {=_xlfn.XLOOKUP(T_Analyse[Code_EPCI],INSEE_EPCI!$A$2:$A$93,INSEE_EPCI!$F$2:$F$93)} -> 21.1 | I5: =(F5-E5)/E5 -> -0.016812999 | J5: =H5*F5/100 -> 14720.204 | K5: =F5/D5 -> 504.43962 | L5: =sum(T_Analyse[Population 2023]-T_Analyse[Formule by Xavier]) -> 0 | M5: =SUMIFS(T_HDF[Population],T_HDF[Code_EPCI],T_Analyse[Code_EPCI]) -> 69764
A6: 200040947 | B6: CA Coeur de Flandre | C6: =COUNTIFS(T_HDF[Code_EPCI],A6) -> 50 | D6: =SUMIFS(T_HDF[Superficie_km2],T_HDF[Code_EPCI],A6) -> 633.92 | E6: {=_xlfn.XLOOKUP(T_Analyse[Code_EPCI],INSEE_EPCI!$A$2:$A$93,INSEE_EPCI!$C$2:$C$93)} -> 102272 | F6: {=_xlfn.XLOOKUP(T_Analyse[Code_EPCI],INSEE_EPCI!$A$2:$A$93,INSEE_EPCI!$D$2:$D$93)} -> 102743 | G6: {=_xlfn.XLOOKUP(T_Analyse[Code_EPCI],INSEE_EPCI!$A$2:$A$93,INSEE_EPCI!$E$2:$E$93)} -> 25990 | H6: {=_xlfn.XLOOKUP(T_Analyse[Code_EPCI],INSEE_EPCI!$A$2:$A$93,INSEE_EPCI!$F$2:$F$93)} -> 11.1 | I6: =(F6-E6)/E6 -> 0.0046053661 | J6: =H6*F6/100 -> 11404.473 | K6: =F6/D6 -> 162.07566 | L6: =sum(T_Analyse[Population 2023]-T_Analyse[Formule by Xavier]) -> 0 | M6: =SUMIFS(T_HDF[Population],T_HDF[Code_EPCI],T_Analyse[Code_EPCI]) -> 102743
A7: 200068047 | B7: CA Creil Sud Oise | C7: =COUNTIFS(T_HDF[Code_EPCI],A7) -> 11 | D7: =SUMIFS(T_HDF[Superficie_km2],T_HDF[Code_EPCI],A7) -> 83.61 | E7: {=_xlfn.XLOOKUP(T_Analyse[Code_EPCI],INSEE_EPCI!$A$2:$A$93,INSEE_EPCI!$C$2:$C$93)} -> 86512 | F7: {=_xlfn.XLOOKUP(T_Analyse[Code_EPCI],INSEE_EPCI!$A$2:$A$93,INSEE_EPCI!$D$2:$D$93)} -> 90234 | G7: {=_xlfn.XLOOKUP(T_Analyse[Code_EPCI],INSEE_EPCI!$A$2:$A$93,INSEE_EPCI!$E$2:$E$93)} -> 19250 | H7: {=_xlfn.XLOOKUP(T_Analyse[Code_EPCI],INSEE_EPCI!$A$2:$A$93,INSEE_EPCI!$F$2:$F$93)} -> 33.5 | I7: =(F7-E7)/E7 -> 0.043022933 | J7: =H7*F7/100 -> 30228.39 | K7: =F7/D7 -> 1079.225 | L7: =sum(T_Analyse[Population 2023]-T_Analyse[Formule by Xavier]) -> 0 | M7: =SUMIFS(T_HDF[Population],T_HDF[Code_EPCI],T_Analyse[Code_EPCI]) -> 90234
A8: 200044618 | B8: CA Douaisis Agglo | C8: =COUNTIFS(T_HDF[Code_EPCI],A8) -> 35 | D8: =SUMIFS(T_HDF[Superficie_km2],T_HDF[Code_EPCI],A8) -> 235.58 | E8: {=_xlfn.XLOOKUP(T_Analyse[Code_EPCI],INSEE_EPCI!$A$2:$A$93,INSEE_EPCI!$C$2:$C$93)} -> 149258 | F8: {=_xlfn.XLOOKUP(T_Analyse[Code_EPCI],INSEE_EPCI!$A$2:$A$93,INSEE_EPCI!$D$2:$D$93)} -> 149282 | G8: {=_xlfn.XLOOKUP(T_Analyse[Code_EPCI],INSEE_EPCI!$A$2:$A$93,INSEE_EPCI!$E$2:$E$93)} -> 22540 | H8: {=_xlfn.XLOOKUP(T_Analyse[Code_EPCI],INSEE_EPCI!$A$2:$A$93,INSEE_EPCI!$F$2:$F$93)} -> 22.4 | I8: =(F8-E8)/E8 -> 0.0001607954 | J8: =H8*F8/100 -> 33439.168 | K8: =F8/D8 -> 633.67858 | L8: =sum(T_Analyse[Population 2023]-T_Analyse[Formule by Xavier]) -> 0 | M8: =SUMIFS(T_HDF[Population],T_HDF[Code_EPCI],T_Analyse[Code_EPCI]) -> 149282
A9: 200090751 | B9: CA Grand Calais Terres et Mers | C9: =COUNTIFS(T_HDF[Code_EPCI],A9) -> 14 | D9: =SUMIFS(T_HDF[Superficie_km2],T_HDF[Code_EPCI],A9) -> 188.92 | E9: {=_xlfn.XLOOKUP(T_Analyse[Code_EPCI],INSEE_EPCI!$A$2:$A$93,INSEE_EPCI!$C$2:$C$93)} -> 105269 | F9: {=_xlfn.XLOOKUP(T_Analyse[Code_EPCI],INSEE_EPCI!$A$2:$A$93,INSEE_EPCI!$D$2:$D$93)} -> 98895 | G9: {=_xlfn.XLOOKUP(T_Analyse[Code_EPCI],INSEE_EPCI!$A$2:$A$93,INSEE_EPCI!$E$2:$E$93)} -> 22150 | H9: {=_xlfn.XLOOKUP(T_Analyse[Code_EPCI],INSEE_EPCI!$A$2:$A$93,INSEE_EPCI!$F$2:$F$93)} -> 23 | I9: =(F9-E9)/E9 -> -0.06054964 | J9: =H9*F9/100 -> 22745.85 | K9: =F9/D9 -> 523.47555 | L9: =sum(T_Analyse[Population 2023]-T_Analyse[Formule by Xavier]) -> 0 | M9: =SUMIFS(T_HDF[Population],T_HDF[Code_EPCI],T_Analyse[Code_EPCI]) -> 98895
A10: 240200477 | B10: CA GrandSoissons Agglomération | C10: =COUNTIFS(T_HDF[Code_EPCI],A10) -> 27 | D10: =SUMIFS(T_HDF[Superficie_km2],T_HDF[Code_EPCI],A10) -> 181 | E10: {=_xlfn.XLOOKUP(T_Analyse[Code_EPCI],INSEE_EPCI!$A$2:$A$93,INSEE_EPCI!$C$2:$C$93)} -> 52328 | F10: {=_xlfn.XLOOKUP(T_Analyse[Code_EPCI],INSEE_EPCI!$A$2:$A$93,INSEE_EPCI!$D$2:$D$93)} -> 51809 | G10: {=_xlfn.XLOOKUP(T_Analyse[Code_EPCI],INSEE_EPCI!$A$2:$A$93,INSEE_EPCI!$E$2:$E$93)} -> 22560 | H10: {=_xlfn.XLOOKUP(T_Analyse[Code_EPCI],INSEE_EPCI!$A$2:$A$93,INSEE_EPCI!$F$2:$F$93)} -> 23.9 | I10: =(F10-E10)/E10 -> -0.0099182082 | J10: =H10*F10/100 -> 12382.351 | K10: =F10/D10 -> 286.23757 | L10: =sum(T_Analyse[Population 2023]-T_Analyse[Formule by Xavier]) -> 0 | M10: =SUMIFS(T_HDF[Population],T_HDF[Code_EPCI],T_Analyse[Code_EPCI]) -> 51809
A11: 200043396 | B11: CA Maubeuge Val de Sambre | C11: =COUNTIFS(T_HDF[Code_EPCI],A11) -> 43 | D11: =SUMIFS(T_HDF[Superficie_km2],T_HDF[Code_EPCI],A11) -> 344.38 | E11: {=_xlfn.XLOOKUP(T_Analyse[Code_EPCI],INSEE_EPCI!$A$2:$A$93,INSEE_EPCI!$C$2:$C$93)} -> 125651 | F11: {=_xlfn.XLOOKUP(T_Analyse[Code_EPCI],INSEE_EPCI!$A$2:$A$93,INSEE_EPCI!$D$2:$D$93)} -> 122247 | G11: {=_xlfn.XLOOKUP(T_Analyse[Code_EPCI],INSEE_EPCI!$A$2:$A$93,INSEE_EPCI!$E$2:$E$93)} -> 20580 | H11: {=_xlfn.XLOOKUP(T_Analyse[Code_EPCI],INSEE_EPCI!$A$2:$A$93,INSEE_EPCI!$F$2:$F$93)} -> 28.6 | I11: =(F11-E11)/E11 -> -0.027090911 | J11: =H11*F11/100 -> 34962.642 | K11: =F11/D11 -> 354.97706 | L11: =sum(T_Analyse[Population 2023]-T_Analyse[Formule by Xavier]) -> 0 | M11: =SUMIFS(T_HDF[Population],T_HDF[Code_EPCI],T_Analyse[Code_EPCI]) -> 122247
A12: 245901160 | B12: CA Valenciennes Métropole | C12: =COUNTIFS(T_HDF[Code_EPCI],A12) -> 35 | D12: =SUMIFS(T_HDF[Superficie_km2],T_HDF[Code_EPCI],A12) -> 262.85 | E12: {=_xlfn.XLOOKUP(T_Analyse[Code_EPCI],INSEE_EPCI!$A$2:$A$93,INSEE_EPCI!$C$2:$C$93)} -> 192594 | F12: {=_xlfn.XLOOKUP(T_Analyse[Code_EPCI],INSEE_EPCI!$A$2:$A$93,INSEE_EPCI!$D$2:$D$93)} -> 191738 | G12: {=_xlfn.XLOOKUP(T_Analyse[Code_EPCI],INSEE_EPCI!$A$2:$A$93,INSEE_EPCI!$E$2:$E$93)} -> 22000 | H12: {=_xlfn.XLOOKUP(T_Analyse[Code_EPCI],INSEE_EPCI!$A$2:$A$93,INSEE_EPCI!$F$2:$F$93)} -> 25 | I12: =(F12-E12)/E12 -> -0.0044445829 | J12: =H12*F12/100 -> 47934.5 | K12: =F12/D12 -> 729.45787 | L12: =sum(T_Analyse[Population 2023]-T_Analyse[Formule by Xavier]) -> 0 | M12: =SUMIFS(T_HDF[Population],T_HDF[Code_EPCI],T_Analyse[Code_EPCI]) -> 191738
A13: 246200299 | B13: CA d'Hénin-Carvin | C13: =COUNTIFS(T_HDF[Code_EPCI],A13) -> 14 | D13: =SUMIFS(T_HDF[Superficie_km2],T_HDF[Code_EPCI],A13) -> 111.99 | E13: {=_xlfn.XLOOKUP(T_Analyse[Code_EPCI],INSEE_EPCI!$A$2:$A$93,INSEE_EPCI!$C$2:$C$93)} -> 125835 | F13: {=_xlfn.XLOOKUP(T_Analyse[Code_EPCI],INSEE_EPCI!$A$2:$A$93,INSEE_EPCI!$D$2:$D$93)} -> 125793 | G13: {=_xlfn.XLOOKUP(T_Analyse[Code_EPCI],INSEE_EPCI!$A$2:$A$93,INSEE_EPCI!$E$2:$E$93)} -> 21790 | H13: {=_xlfn.XLOOKUP(T_Analyse[Code_EPCI],INSEE_EPCI!$A$2:$A$93,INSEE_EPCI!$F$2:$F$93)} -> 23.3 | I13: =(F13-E13)/E13 -> -0.00033377041 | J13: =H13*F13/100 -> 29309.769 | K13: =F13/D13 -> 1123.2521 | L13: =sum(T_Analyse[Population 2023]-T_Analyse[Formule by Xavier]) -> 0 | M13: =SUMIFS(T_HDF[Population],T_HDF[Code_EPCI],T_Analyse[Code_EPCI]) -> 125793
A14: 200072460 | B14: CA de Béthune-Bruay, Artois-Lys Romane | C14: =COUNTIFS(T_HDF[Code_EPCI],A14) -> 100 | D14: =SUMIFS(T_HDF[Superficie_km2],T_HDF[Code_EPCI],A14) -> 646.3 | E14: {=_xlfn.XLOOKUP(T_Analyse[Code_EPCI],INSEE_EPCI!$A$2:$A$93,INSEE_EPCI!$C$2:$C$93)} -> 276895 | F14: {=_xlfn.XLOOKUP(T_Analyse[Code_EPCI],INSEE_EPCI!$A$2:$A$93,INSEE_EPCI!$D$2:$D$93)} -> 275028 | G14: {=_xlfn.XLOOKUP(T_Analyse[Code_EPCI],INSEE_EPCI!$A$2:$A$93,INSEE_EPCI!$E$2:$E$93)} -> 22990 | H14: {=_xlfn.XLOOKUP(T_Analyse[Code_EPCI],INSEE_EPCI!$A$2:$A$93,INSEE_EPCI!$F$2:$F$93)} -> 19.4 | I14: =(F14-E14)/E14 -> -0.0067426281 | J14: =H14*F14/100 -> 53355.432 | K14: =F14/D14 -> 425.54232 | L14: =sum(T_Analyse[Population 2023]-T_Analyse[Formule by Xavier]) -> 0 | M14: =SUMIFS(T_HDF[Population],T_HDF[Code_EPCI],T_Analyse[Code_EPCI]) -> 275028
... A94: 200093201 | B94: Métropole Européenne de Lille | C94: =COUNTIFS(T_HDF[Code_EPCI],A94) -> 95 | D94: =SUMIFS(T_HDF[Superficie_km2],T_HDF[Code_EPCI],A94) -> 672.78 | E94: {=_xlfn.XLOOKUP(T_Analyse[Code_EPCI],INSEE_EPCI!$A$2:$A$93,INSEE_EPCI!$C$2:$C$93)} -> 1170630 | F94: {=_xlfn.XLOOKUP(T_Analyse[Code_EPCI],INSEE_EPCI!$A$2:$A$93,INSEE_EPCI!$D$2:$D$93)} -> 1195234 | G94: {=_xlfn.XLOOKUP(T_Analyse[Code_EPCI],INSEE_EPCI!$A$2:$A$93,INSEE_EPCI!$E$2:$E$93)} -> 24430 | H94: {=_xlfn.XLOOKUP(T_Analyse[Code_EPCI],INSEE_EPCI!$A$2:$A$93,INSEE_EPCI!$F$2:$F$93)} -> 21.4 | I94: =(F94-E94)/E94 -> 0.021017743 | J94: =H94*F94/100 -> 255780.08 | K94: =F94/D94 -> 1776.5599 | L94: =sum(T_Analyse[Population 2023]-T_Analyse[Formule by Xavier]) -> 0 | M94: =SUMIFS(T_HDF[Population],T_HDF[Code_EPCI],T_Analyse[Code_EPCI]) -> 1195234

Sheet Indicateurs
B1: taux de pauvreté | C1: niveau de vie médian
A2: minimum | B2: =MIN(T_Analyse[Taux de pauvreté 2023]) -> 7 | C2: =MIN(T_Analyse[Niveau de vie médian 2023]) -> 19250
A3: Q1 | B3: =QUARTILE(T_Analyse[Taux de pauvreté 2023],1) -> 12 | C3: =QUARTILE(T_Analyse[Niveau de vie médian 2023], 1) -> 23147.5
A4: médiane | B4: =MEDIAN(T_Analyse[Taux de pauvreté 2023]) -> 14.5 | C4: =MEDIAN(T_Analyse[Niveau de vie médian 2023]) -> 24350
A5: Q3 | B5: =QUARTILE(T_Analyse[Taux de pauvreté 2023],3) -> 20.15 | C5: =QUARTILE(T_Analyse[Niveau de vie médian 2023], 3) -> 25687.5
A6: maximum | B6: =MAX(T_Analyse[Taux de pauvreté 2023]) -> 33.5 | C6: =MAX(T_Analyse[Niveau de vie médian 2023]) -> 34810
A7: moyenne simple | B7: =AVERAGE(T_Analyse[Taux de pauvreté 2023]) -> 16.086957 | C7: =AVERAGE(T_Analyse[Niveau de vie médian 2023]) -> 24483.152
A8: moyenne pondérée par la population 2023 | B8: =IFERROR(__xludf.DUMMYFUNCTION("AVERAGE.WEIGHTED(T_Analyse[Taux de pauvreté 2023],T_Analyse[Population 2023])"),19.063895040179556) -> 19.063895 | C8: =SUMPRODUCT(T_Analyse[Niveau de vie médian 2023],T_Analyse[Population 2023])/SUM(T_Analyse[Population 2023]) -> 23978.569
A9: Que dit l'écart ? | B9: La moyenne pondérée (19,06 %) supérieure à la moyenne simple (16,09 %) indique que le taux de pauvreté est plus élevé dans les territoires les plus peuplés. | C9: a moyenne pondérée (23 979 €) inférieure à la moyenne simple (24 483 €) indique que le niveau de vie médian est plus faible dans les territoires les plus peuplés.

Sheet Manquants
B1: taux de pauvreté | C1: niveau de vie médian
A2: non publié | B2: =COUNTIF(T_INSEE[Taux_pauvrete_2023], "non publié") -> 3262 | C2: =COUNTIF(T_INSEE[Niveau_vie_median_2023], "non publié") -> 288
A3: nombre d'habitans non publié | B3: =SUMIFS(T_INSEE[Population_2023],T_INSEE[Taux_pauvrete_2023],"non publié") -> 1657654 | C3: =SUMIFS(T_INSEE[Population_2023], T_INSEE[Niveau_vie_median_2023], "non publié") -> 20290
A4: Population_2023 (Commune_HDF) | B4: =SUM(T_HDF[Population]) -> 5992194
A5: Population_2023 (INSEE_EPCI) | B5: =SUM(T_EPCI[Population_2023]) -> 6030803 | C5: ce chiffre comprend les deux communautées de communes de CC des Villes Soeurs (35390) et CC Interrégionale Aumale - Blangy-sur-Bresle (21154) avec des communes en normandies.
C10: =SUM(B10-E10) -> 0
C11: =SUM(B11-E11) -> 0
C12: =SUM(B12-E12) -> 0
C13: =SUM(B13-E13) -> 0
C14: =SUM(B14-E14) -> 0
C15: =SUM(B15-E15) -> 0
C16: =SUM(B16-E16) -> 0
C17: =SUM(B17-E17) -> 0
C18: =SUM(B18-E18) -> 0
C19: =SUM(B19-E19) -> 0
C20: =SUM(B20-E20) -> 0
C21: =SUM(B21-E21) -> 0
... C102: =SUM(B102-E102) -> 38609

Sheet Méthode
A1: indicateurs de territoires prioritaire
A2: indicateurs | B2: choix
A3: taux de pauvreté | B3: oui
A4: nombre de personnes pauvres | B4: oui
A5: évolution de la population | B5: non
A6: niveau de vie médian | B6: non
A7: Justification

Sheet Copie de Communes_HDF
A1: Code_INSEE | B1: Commune | C1: Departement | D1: EPCI | E1: Code_EPCI | F1: Population | G1: Superficie_km2 | H1: Densite_hab_km2 | I1: Taille_commune
A2: 02001 | B2: Abbécourt | C2: Aisne | D2: CA Chauny Tergnier La Fère | E2: 200071785 | F2: 518 | G2: 5.98 | H2: 86.6 | I2: 500 a 2 000
A3: 02002 | B3: Achery | C3: Aisne | D3: CA Chauny Tergnier La Fère | E3: 200071785 | F3: 584 | G3: 6.95 | H3: 84 | I3: 500 a 2 000
A4: 02003 | B4: Acy | C4: Aisne | D4: CA GrandSoissons Agglomération | E4: 240200477 | F4: 1004 | G4: 11.55 | H4: 86.9 | I4: 500 a 2 000
A5: 02004 | B5: Agnicourt-et-Séchelles | C5: Aisne | D5: CC du Pays de la Serre | E5: 240200469 | F5: 189 | G5: 10.72 | H5: 17.6 | I5: < 500 hab.
A6: 02005 | B6: Aguilcourt | C6: Aisne | D6: CC de la Champagne Picarde | E6: 240200576 | F6: 417 | G6: 10.61 | H6: 39.3 | I6: < 500 hab.
A7: 02006 | B7: Aisonville-et-Bernoville | C7: Aisne | D7: CC Thiérache Sambre et Oise | E7: 200071983 | F7: 259 | G7: 8.71 | H7: 29.7 | I7: < 500 hab.
A8: 02007 | B8: Aizelles | C8: Aisne | D8: CC du Chemin des Dames | E8: 240200592 | F8: 118 | G8: 4.88 | H8: 24.2 | I8: < 500 hab.
A9: 02008 | B9: Aizy-Jouy | C9: Aisne | D9: CC du Val de l'Aisne | E9: 240200501 | F9: 306 | G9: 14.72 | H9: 20.8 | I9: < 500 hab.
A10: 02009 | B10: Alaincourt | C10: Aisne | D10: CC du Val de l'Oise | E10: 200040426 | F10: 517 | G10: 5.99 | H10: 86.3 | I10: 500 a 2 000
A11: 02010 | B11: Allemant | C11: Aisne | D11: CC du Val de l'Aisne | E11: 240200501 | F11: 163 | G11: 5.16 | H11: 31.6 | I11: < 500 hab.
A12: 02011 | B12: Ambleny | C12: Aisne | D12: CC Retz en Valois | E12: 200071991 | F12: 1205 | G12: 17.24 | H12: 69.9 | I12: 500 a 2 000
A13: 02012 | B13: Ambrief | C13: Aisne | D13: CC du Canton d'Oulchy-le-Château | E13: 240200519 | F13: 79 | G13: 4.48 | H13: 17.6 | I13: < 500 hab.
... A3783: 80836 | B3783: Yonval | C3783: Somme | D3783: CA de la Baie de Somme | E3783: 200070993 | F3783: 243 | G3783: 3.99 | H3783: 60.9 | I3783: < 500 hab.

Sheet Copie de INSEE_Communes
A1: Code_INSEE | B1: Commune | C1: Population_2017 | D1: Population_2023 | E1: Niveau_vie_median_2023 | F1: Taux_pauvrete_2023
A2: 02001 | B2: Abbécourt | C2: 498 | D2: 518 | E2: 24700 | F2: non publié
A3: 02002 | B3: Achery | C3: 598 | D3: 584 | E3: 25260 | F3: non publié
A4: 02003 | B4: Acy | C4: 1012 | D4: 1004 | E4: 26000 | F4: non publié
A5: 02004 | B5: Agnicourt-et-Séchelles | C5: 177 | D5: 189 | E5: 21320 | F5: non publié
A6: 02005 | B6: Aguilcourt | C6: 384 | D6: 417 | E6: 27790 | F6: non publié
A7: 02006 | B7: Aisonville-et-Bernoville | C7: 255 | D7: 259 | E7: 25470 | F7: non publié
A8: 02007 | B8: Aizelles | C8: 125 | D8: 118 | E8: 26000 | F8: non publié
A9: 02008 | B9: Aizy-Jouy | C9: 291 | D9: 306 | E9: 26290 | F9: non publié
A10: 02009 | B10: Alaincourt | C10: 543 | D10: 517 | E10: 25820 | F10: non publié
A11: 02010 | B11: Allemant | C11: 177 | D11: 163 | E11: 26140 | F11: non publié
A12: 02011 | B12: Ambleny | C12: 1155 | D12: 1205 | E12: 27570 | F12: non publié
A13: 02012 | B13: Ambrief | C13: 70 | D13: 79 | E13: non publié | F13: non publié
A14: 02013 | B14: Amifontaine | C14: 404 | D14: 391 | E14: 27200 | F14: non publié
A15: 02014 | B15: Amigny-Rouy | C15: 744 | D15: 707 | E15: 25340 | F15: non publié
A16: 02015 | B16: Ancienville | C16: 75 | D16: 78 | E16: non publié | F16: non publié
A17: 02016 | B17: Andelain | C17: 228 | D17: 212 | E17: 24940 | F17: non publié
A18: 02017 | B18: Anguilcourt-le-Sart | C18: 315 | D18: 274 | E18: 25510 | F18: non publié
A19: 02018 | B19: Anizy-le-Grand | C19: 2533 | D19: 2472 | E19: 23090 | F19: 16
A20: 02019 | B20: Annois | C20: 364 | D20: 349 | E20: 23740 | F20: non publié
A21: 02020 | B21: Any-Martin-Rieux | C21: 456 | D21: 456 | E21: 23100 | F21: non publié
A22: 02021 | B22: Archon | C22: 87 | D22: 76 | E22: non publié | F22: non publié
A23: 02022 | B23: Arcy-Sainte-Restitue | C23: 403 | D23: 396 | E23: 25950 | F23: non publié
A24: 02023 | B24: Armentières-sur-Ourcq | C24: 103 | D24: 96 | E24: non publié | F24: non publié
A25: 02024 | B25: Arrancy | C25: 53 | D25: 45 | E25: non publié | F25: non publié
A26: 02025 | B26: Artemps | C26: 371 | D26: 361 | E26: 26150 | F26: non publié
A27: 02027 | B27: Assis-sur-Serre | C27: 222 | D27: 209 | E27: 22280 | F27: non publié
A28: 02028 | B28: Athies-sous-Laon | C28: 2604 | D28: 2578 | E28: 25840 | F28: 11
A29: 02029 | B29: Attilly | C29: 363 | D29: 337 | E29: 27020 | F29: non publié
A30: 02030 | B30: Aubencheul-aux-Bois | C30: 269 | D30: 238 | E30: 25630 | F30: non publié
A31: 02031 | B31: Aubenton | C31: 657 | D31: 658 | E31: 20520 | F31: non publié
A32: 02032 | B32: Aubigny-aux-Kaisnes | C32: 253 | D32: 231 | E32: 21870 | F32: non publié
A33: 02033 | B33: Aubigny-en-Laonnois | C33: 105 | D33: 102 | E33: 27820 | F33: non publié
A34: 02034 | B34: Audignicourt | C34: 118 | D34: 104 | E34: 26480 | F34: non publié
A35: 02035 | B35: Audigny | C35: 279 | D35: 273 | E35: 24790 | F35: non publié
A36: 02036 | B36: Augy | C36: 82 | D36: 72 | E36: non publié | F36: non publié
A37: 02037 | B37: Aulnois-sous-Laon | C37: 1422 | D37: 1348 | E37: 24480 | F37: non publié
A38: 02038 | B38: Les Autels | C38: 57 | D38: 62 | E38: non publié | F38: non publié
A39: 02039 | B39: Autremencourt | C39: 169 | D39: 176 | E39: 21760 | F39: non publié
A40: 02040 | B40: Autreppes | C40: 178 | D40: 175 | E40: 23920 | F40: non publié
...

Sheet Copie de INSEE_EPCI
A1: Code_EPCI | B1: Nom_EPCI | C1: Population_2017 | D1: Population_2023 | E1: Niveau_vie_median_2023 | F1: Taux_pauvrete_2023
A2: 248000531 | B2: CA Amiens Métropole | C2: 180816 | D2: 184392 | E2: 23640 | F2: 23.5
A3: 200071785 | B3: CA Chauny Tergnier La Fère | C3: 55470 | D3: 54027 | E3: 22590 | F3: 21.6
A4: 245901152 | B4: CA Coeur d'Ostrevent | C4: 70957 | D4: 69764 | E4: 22340 | F4: 21.1
A5: 200040947 | B5: CA Coeur de Flandre | C5: 102272 | D5: 102743 | E5: 25990 | F5: 11.1
A6: 200068047 | B6: CA Creil Sud Oise | C6: 86512 | D6: 90234 | E6: 19250 | F6: 33.5
A7: 200044618 | B7: CA Douaisis Agglo | C7: 149258 | D7: 149282 | E7: 22540 | F7: 22.4
A8: 200090751 | B8: CA Grand Calais Terres et Mers | C8: 105269 | D8: 98895 | E8: 22150 | F8: 23
A9: 240200477 | B9: CA GrandSoissons Agglomération | C9: 52328 | D9: 51809 | E9: 22560 | F9: 23.9
A10: 200043396 | B10: CA Maubeuge Val de Sambre | C10: 125651 | D10: 122247 | E10: 20580 | F10: 28.6
A11: 245901160 | B11: CA Valenciennes Métropole | C11: 192594 | D11: 191738 | E11: 22000 | F11: 25
A12: 246200299 | B12: CA d'Hénin-Carvin | C12: 125835 | D12: 125793 | E12: 21790 | F12: 23.3
A13: 200072460 | B13: CA de Béthune-Bruay, Artois-Lys Romane | C13: 276895 | D13: 275028 | E13: 22990 | F13: 19.4
... A93: 200093201 | B93: Métropole Européenne de Lille | C93: 1170630 | D93: 1195234 | E93: 24430 | F93: 21.4

Sheet INSEE_EPCI
A1: Code_EPCI | B1: Nom_EPCI | C1: Population_2017 | D1: Population_2023 | E1: Niveau_vie_median_2023 | F1: Taux_pauvrete_2023
A2: 248000531 | B2: CA Amiens Métropole | C2: 180816 | D2: 184392 | E2: 23640 | F2: 23.5
A3: 200071785 | B3: CA Chauny Tergnier La Fère | C3: 55470 | D3: 54027 | E3: 22590 | F3: 21.6
A4: 245901152 | B4: CA Coeur d'Ostrevent | C4: 70957 | D4: 69764 | E4: 22340 | F4: 21.1
A5: 200040947 | B5: CA Coeur de Flandre | C5: 102272 | D5: 102743 | E5: 25990 | F5: 11.1
A6: 200068047 | B6: CA Creil Sud Oise | C6: 86512 | D6: 90234 | E6: 19250 | F6: 33.5
A7: 200044618 | B7: CA Douaisis Agglo | C7: 149258 | D7: 149282 | E7: 22540 | F7: 22.4
A8: 200090751 | B8: CA Grand Calais Terres et Mers | C8: 105269 | D8: 98895 | E8: 22150 | F8: 23
A9: 240200477 | B9: CA GrandSoissons Agglomération | C9: 52328 | D9: 51809 | E9: 22560 | F9: 23.9
A10: 200043396 | B10: CA Maubeuge Val de Sambre | C10: 125651 | D10: 122247 | E10: 20580 | F10: 28.6
A11: 245901160 | B11: CA Valenciennes Métropole | C11: 192594 | D11: 191738 | E11: 22000 | F11: 25
A12: 246200299 | B12: CA d'Hénin-Carvin | C12: 125835 | D12: 125793 | E12: 21790 | F12: 23.3
A13: 200072460 | B13: CA de Béthune-Bruay, Artois-Lys Romane | C13: 276895 | D13: 275028 | E13: 22990 | F13: 19.4
... A93: 200093201 | B93: Métropole Européenne de Lille | C93: 1170630 | D93: 1195234 | E93: 24430 | F93: 21.4

Sheet INSEE_Communes
A1: Code_INSEE | B1: Commune | C1: Population_2017 | D1: Population_2023 | E1: Niveau_vie_median_2023 | F1: Taux_pauvrete_2023
A2: 02001 | B2: Abbécourt | C2: 498 | D2: 518 | E2: 24700 | F2: non publié
A3: 02002 | B3: Achery | C3: 598 | D3: 584 | E3: 25260 | F3: non publié
A4: 02003 | B4: Acy | C4: 1012 | D4: 1004 | E4: 26000 | F4: non publié
A5: 02004 | B5: Agnicourt-et-Séchelles | C5: 177 | D5: 189 | E5: 21320 | F5: non publié
A6: 02005 | B6: Aguilcourt | C6: 384 | D6: 417 | E6: 27790 | F6: non publié
A7: 02006 | B7: Aisonville-et-Bernoville | C7: 255 | D7: 259 | E7: 25470 | F7: non publié
A8: 02007 | B8: Aizelles | C8: 125 | D8: 118 | E8: 26000 | F8: non publié
A9: 02008 | B9: Aizy-Jouy | C9: 291 | D9: 306 | E9: 26290 | F9: non publié
A10: 02009 | B10: Alaincourt | C10: 543 | D10: 517 | E10: 25820 | F10: non publié
A11: 02010 | B11: Allemant | C11: 177 | D11: 163 | E11: 26140 | F11: non publié
A12: 02011 | B12: Ambleny | C12: 1155 | D12: 1205 | E12: 27570 | F12: non publié
A13: 02012 | B13: Ambrief | C13: 70 | D13: 79 | E13: non publié | F13: non publié
A14: 02013 | B14: Amifontaine | C14: 404 | D14: 391 | E14: 27200 | F14: non publié
A15: 02014 | B15: Amigny-Rouy | C15: 744 | D15: 707 | E15: 25340 | F15: non publié
A16: 02015 | B16: Ancienville | C16: 75 | D16: 78 | E16: non publié | F16: non publié
A17: 02016 | B17: Andelain | C17: 228 | D17: 212 | E17: 24940 | F17: non publié
A18: 02017 | B18: Anguilcourt-le-Sart | C18: 315 | D18: 274 | E18: 25510 | F18: non publié
A19: 02018 | B19: Anizy-le-Grand | C19: 2533 | D19: 2472 | E19: 23090 | F19: 16
A20: 02019 | B20: Annois | C20: 364 | D20: 349 | E20: 23740 | F20: non publié
A21: 02020 | B21: Any-Martin-Rieux | C21: 456 | D21: 456 | E21: 23100 | F21: non publié
A22: 02021 | B22: Archon | C22: 87 | D22: 76 | E22: non publié | F22: non publié
A23: 02022 | B23: Arcy-Sainte-Restitue | C23: 403 | D23: 396 | E23: 25950 | F23: non publié
A24: 02023 | B24: Armentières-sur-Ourcq | C24: 103 | D24: 96 | E24: non publié | F24: non publié
A25: 02024 | B25: Arrancy | C25: 53 | D25: 45 | E25: non publié | F25: non publié
A26: 02025 | B26: Artemps | C26: 371 | D26: 361 | E26: 26150 | F26: non publié
A27: 02027 | B27: Assis-sur-Serre | C27: 222 | D27: 209 | E27: 22280 | F27: non publié
A28: 02028 | B28: Athies-sous-Laon | C28: 2604 | D28: 2578 | E28: 25840 | F28: 11
A29: 02029 | B29: Attilly | C29: 363 | D29: 337 | E29: 27020 | F29: non publié
A30: 02030 | B30: Aubencheul-aux-Bois | C30: 269 | D30: 238 | E30: 25630 | F30: non publié
A31: 02031 | B31: Aubenton | C31: 657 | D31: 658 | E31: 20520 | F31: non publié
A32: 02032 | B32: Aubigny-aux-Kaisnes | C32: 253 | D32: 231 | E32: 21870 | F32: non publié
A33: 02033 | B33: Aubigny-en-Laonnois | C33: 105 | D33: 102 | E33: 27820 | F33: non publié
A34: 02034 | B34: Audignicourt | C34: 118 | D34: 104 | E34: 26480 | F34: non publié
A35: 02035 | B35: Audigny | C35: 279 | D35: 273 | E35: 24790 | F35: non publié
A36: 02036 | B36: Augy | C36: 82 | D36: 72 | E36: non publié | F36: non publié
A37: 02037 | B37: Aulnois-sous-Laon | C37: 1422 | D37: 1348 | E37: 24480 | F37: non publié
A38: 02038 | B38: Les Autels | C38: 57 | D38: 62 | E38: non publié | F38: non publié
A39: 02039 | B39: Autremencourt | C39: 169 | D39: 176 | E39: 21760 | F39: non publié
A40: 02040 | B40: Autreppes | C40: 178 | D40: 175 | E40: 23920 | F40: non publié
...

Sheet Communes_HDF
A1: Code_INSEE | B1: Commune | C1: Departement | D1: EPCI | E1: Code_EPCI | F1: Population | G1: Superficie_km2 | H1: Densite_hab_km2 | I1: Taille_commune
A2: 02001 | B2: Abbécourt | C2: Aisne | D2: CA Chauny Tergnier La Fère | E2: 200071785 | F2: 518 | G2: 5.98 | H2: 86.6 | I2: 500 a 2 000
A3: 02002 | B3: Achery | C3: Aisne | D3: CA Chauny Tergnier La Fère | E3: 200071785 | F3: 584 | G3: 6.95 | H3: 84 | I3: 500 a 2 000
A4: 02003 | B4: Acy | C4: Aisne | D4: CA GrandSoissons Agglomération | E4: 240200477 | F4: 1004 | G4: 11.55 | H4: 86.9 | I4: 500 a 2 000
A5: 02004 | B5: Agnicourt-et-Séchelles | C5: Aisne | D5: CC du Pays de la Serre | E5: 240200469 | F5: 189 | G5: 10.72 | H5: 17.6 | I5: < 500 hab.
A6: 02005 | B6: Aguilcourt | C6: Aisne | D6: CC de la Champagne Picarde | E6: 240200576 | F6: 417 | G6: 10.61 | H6: 39.3 | I6: < 500 hab.
A7: 02006 | B7: Aisonville-et-Bernoville | C7: Aisne | D7: CC Thiérache Sambre et Oise | E7: 200071983 | F7: 259 | G7: 8.71 | H7: 29.7 | I7: < 500 hab.
A8: 02007 | B8: Aizelles | C8: Aisne | D8: CC du Chemin des Dames | E8: 240200592 | F8: 118 | G8: 4.88 | H8: 24.2 | I8: < 500 hab.
A9: 02008 | B9: Aizy-Jouy | C9: Aisne | D9: CC du Val de l'Aisne | E9: 240200501 | F9: 306 | G9: 14.72 | H9: 20.8 | I9: < 500 hab.
A10: 02009 | B10: Alaincourt | C10: Aisne | D10: CC du Val de l'Oise | E10: 200040426 | F10: 517 | G10: 5.99 | H10: 86.3 | I10: 500 a 2 000
A11: 02010 | B11: Allemant | C11: Aisne | D11: CC du Val de l'Aisne | E11: 240200501 | F11: 163 | G11: 5.16 | H11: 31.6 | I11: < 500 hab.
A12: 02011 | B12: Ambleny | C12: Aisne | D12: CC Retz en Valois | E12: 200071991 | F12: 1205 | G12: 17.24 | H12: 69.9 | I12: 500 a 2 000
A13: 02012 | B13: Ambrief | C13: Aisne | D13: CC du Canton d'Oulchy-le-Château | E13: 240200519 | F13: 79 | G13: 4.48 | H13: 17.6 | I13: < 500 hab.
... A3783: 80836 | B3783: Yonval | C3783: Somme | D3783: CA de la Baie de Somme | E3783: 200070993 | F3783: 243 | G3783: 3.99 | H3783: 60.9 | I3783: < 500 hab.
